
import traceback
# Syntax error can not be handled by the exception
try:
    """  
    
    a = 10
    print("Welcome)
    # c = a/0
    print("Line2")
    
    """

    # Example 2
    """
    new_dict = {
        'age' : '25',
        'salary' : 28000
        'pin' : 800000
    }
    """

    # Example 3
    # pass = 6



except Exception as e:
    print("Exception occurred")
    # print(traceback.print_exc())